Failure # 1 (occurred at 2022-04-26_16-30-24)
Traceback (most recent call last):
  File "/opt/anaconda3/envs/MIMOSA-ML/lib/python3.9/site-packages/ray/tune/ray_trial_executor.py", line 901, in get_next_executor_event
    future_result = ray.get(ready_future)
  File "/opt/anaconda3/envs/MIMOSA-ML/lib/python3.9/site-packages/ray/_private/client_mode_hook.py", line 105, in wrapper
    return func(*args, **kwargs)
  File "/opt/anaconda3/envs/MIMOSA-ML/lib/python3.9/site-packages/ray/worker.py", line 1809, in get
    raise value.as_instanceof_cause()
ray.exceptions.RayTaskError(TuneError): [36mray::ImplicitFunc.train()[39m (pid=21371, ip=127.0.0.1, repr=func)
  File "/opt/anaconda3/envs/MIMOSA-ML/lib/python3.9/site-packages/ray/tune/trainable.py", line 349, in train
    result = self.step()
  File "/opt/anaconda3/envs/MIMOSA-ML/lib/python3.9/site-packages/ray/tune/function_runner.py", line 403, in step
    self._report_thread_runner_error(block=True)
  File "/opt/anaconda3/envs/MIMOSA-ML/lib/python3.9/site-packages/ray/tune/function_runner.py", line 567, in _report_thread_runner_error
    raise TuneError(
ray.tune.error.TuneError: Trial raised an exception. Traceback:
[36mray::ImplicitFunc.train()[39m (pid=21371, ip=127.0.0.1, repr=func)
  File "/opt/anaconda3/envs/MIMOSA-ML/lib/python3.9/site-packages/ray/tune/function_runner.py", line 272, in run
    self._entrypoint()
  File "/opt/anaconda3/envs/MIMOSA-ML/lib/python3.9/site-packages/ray/tune/function_runner.py", line 348, in entrypoint
    return self._trainable_func(
  File "/opt/anaconda3/envs/MIMOSA-ML/lib/python3.9/site-packages/ray/tune/function_runner.py", line 640, in _trainable_func
    output = fn()
  File "/Users/Zachary/Desktop/School/Vandy/Masters/M_Year1/Spring_2022/CS_8395_04/project/MIMOSA/ml/learn/__init__.py", line 296, in train
    config = create_config(args)
  File "/Users/Zachary/Desktop/School/Vandy/Masters/M_Year1/Spring_2022/CS_8395_04/project/MIMOSA/ml/learn/__init__.py", line 54, in create_config
    dataset = datasets.build_dataset(args)
  File "/Users/Zachary/Desktop/School/Vandy/Masters/M_Year1/Spring_2022/CS_8395_04/project/MIMOSA/ml/learn/datasets/__init__.py", line 11, in build_dataset
    dataset = ImageDatasets.MalwareImageDataset(args['examples_dir'], args['labels_csv'], transform=transform, sz=tuple(args['size']))
  File "/Users/Zachary/Desktop/School/Vandy/Masters/M_Year1/Spring_2022/CS_8395_04/project/MIMOSA/ml/learn/datasets/ImageDatasets.py", line 20, in __init__
    self.labels = pd.read_csv(labels_csv) if '.tsv' not in labels_csv else pd.read_csv(labels_csv, sep='\t')
  File "/opt/anaconda3/envs/MIMOSA-ML/lib/python3.9/site-packages/pandas/util/_decorators.py", line 311, in wrapper
    return func(*args, **kwargs)
  File "/opt/anaconda3/envs/MIMOSA-ML/lib/python3.9/site-packages/pandas/io/parsers/readers.py", line 680, in read_csv
    return _read(filepath_or_buffer, kwds)
  File "/opt/anaconda3/envs/MIMOSA-ML/lib/python3.9/site-packages/pandas/io/parsers/readers.py", line 575, in _read
    parser = TextFileReader(filepath_or_buffer, **kwds)
  File "/opt/anaconda3/envs/MIMOSA-ML/lib/python3.9/site-packages/pandas/io/parsers/readers.py", line 933, in __init__
    self._engine = self._make_engine(f, self.engine)
  File "/opt/anaconda3/envs/MIMOSA-ML/lib/python3.9/site-packages/pandas/io/parsers/readers.py", line 1217, in _make_engine
    self.handles = get_handle(  # type: ignore[call-overload]
  File "/opt/anaconda3/envs/MIMOSA-ML/lib/python3.9/site-packages/pandas/io/common.py", line 789, in get_handle
    handle = open(
FileNotFoundError: [Errno 2] No such file or directory: 'data/config_multilabel.csv'

