Failure # 1 (occurred at 2022-04-26_16-33-55)
Traceback (most recent call last):
  File "/opt/anaconda3/envs/MIMOSA-ML/lib/python3.9/site-packages/ray/tune/ray_trial_executor.py", line 901, in get_next_executor_event
    future_result = ray.get(ready_future)
  File "/opt/anaconda3/envs/MIMOSA-ML/lib/python3.9/site-packages/ray/_private/client_mode_hook.py", line 105, in wrapper
    return func(*args, **kwargs)
  File "/opt/anaconda3/envs/MIMOSA-ML/lib/python3.9/site-packages/ray/worker.py", line 1809, in get
    raise value.as_instanceof_cause()
ray.exceptions.RayTaskError(TuneError): [36mray::ImplicitFunc.train()[39m (pid=22061, ip=127.0.0.1, repr=func)
  File "/opt/anaconda3/envs/MIMOSA-ML/lib/python3.9/site-packages/ray/tune/trainable.py", line 349, in train
    result = self.step()
  File "/opt/anaconda3/envs/MIMOSA-ML/lib/python3.9/site-packages/ray/tune/function_runner.py", line 403, in step
    self._report_thread_runner_error(block=True)
  File "/opt/anaconda3/envs/MIMOSA-ML/lib/python3.9/site-packages/ray/tune/function_runner.py", line 567, in _report_thread_runner_error
    raise TuneError(
ray.tune.error.TuneError: Trial raised an exception. Traceback:
[36mray::ImplicitFunc.train()[39m (pid=22061, ip=127.0.0.1, repr=func)
  File "/opt/anaconda3/envs/MIMOSA-ML/lib/python3.9/site-packages/ray/tune/function_runner.py", line 272, in run
    self._entrypoint()
  File "/opt/anaconda3/envs/MIMOSA-ML/lib/python3.9/site-packages/ray/tune/function_runner.py", line 348, in entrypoint
    return self._trainable_func(
  File "/opt/anaconda3/envs/MIMOSA-ML/lib/python3.9/site-packages/ray/tune/function_runner.py", line 640, in _trainable_func
    output = fn()
  File "/Users/Zachary/Desktop/School/Vandy/Masters/M_Year1/Spring_2022/CS_8395_04/project/MIMOSA/ml/learn/__init__.py", line 356, in train
    train_loss, train_metrics = train_epoch(net, device, train_loader, criterion, classes, optimizer, **train_kwargs)
  File "/Users/Zachary/Desktop/School/Vandy/Masters/M_Year1/Spring_2022/CS_8395_04/project/MIMOSA/ml/learn/__init__.py", line 136, in train_epoch
    mtr = metrics.calculate_metrics(output, labels.numpy())
AttributeError: 'numpy.ndarray' object has no attribute 'numpy'

